Workbook

Sheet Overview
A1: Max Player QA
A2: Cases come from the current source, not from a generic MX Player checklist. There is no login screen.
A4: Screen tab | B4: Open | C4: Cases | D4: P0 | E4: P1 | F4: P2 | G4: Android Pass | H4: Android Fail | I4: Not run
A5: App Shell | B5: Go to App Shell | C5: =COUNTA('App Shell'!C:C)-1 | D5: =COUNTIF('App Shell'!J:J,"P0") | E5: =COUNTIF('App Shell'!J:J,"P1") | F5: =COUNTIF('App Shell'!J:J,"P2") | G5: =COUNTIF('App Shell'!K:K,"Pass") | H5: =COUNTIF('App Shell'!K:K,"Fail") | I5: =C5-G5-H5-COUNTIF('App Shell'!K:K,"Blocked")-COUNTIF('App Shell'!K:K,"N/A")
A6: Home | B6: Go to Home | C6: =COUNTA(Home!C:C)-1 | D6: =COUNTIF(Home!J:J,"P0") | E6: =COUNTIF(Home!J:J,"P1") | F6: =COUNTIF(Home!J:J,"P2") | G6: =COUNTIF(Home!K:K,"Pass") | H6: =COUNTIF(Home!K:K,"Fail") | I6: =C6-G6-H6-COUNTIF(Home!K:K,"Blocked")-COUNTIF(Home!K:K,"N/A")
A7: Folder | B7: Go to Folder | C7: =COUNTA(Folder!C:C)-1 | D7: =COUNTIF(Folder!J:J,"P0") | E7: =COUNTIF(Folder!J:J,"P1") | F7: =COUNTIF(Folder!J:J,"P2") | G7: =COUNTIF(Folder!K:K,"Pass") | H7: =COUNTIF(Folder!K:K,"Fail") | I7: =C7-G7-H7-COUNTIF(Folder!K:K,"Blocked")-COUNTIF(Folder!K:K,"N/A")
A8: Search | B8: Go to Search | C8: =COUNTA(Search!C:C)-1 | D8: =COUNTIF(Search!J:J,"P0") | E8: =COUNTIF(Search!J:J,"P1") | F8: =COUNTIF(Search!J:J,"P2") | G8: =COUNTIF(Search!K:K,"Pass") | H8: =COUNTIF(Search!K:K,"Fail") | I8: =C8-G8-H8-COUNTIF(Search!K:K,"Blocked")-COUNTIF(Search!K:K,"N/A")
A9: File Actions | B9: Go to File Actions | C9: =COUNTA('File Actions'!C:C)-1 | D9: =COUNTIF('File Actions'!J:J,"P0") | E9: =COUNTIF('File Actions'!J:J,"P1") | F9: =COUNTIF('File Actions'!J:J,"P2") | G9: =COUNTIF('File Actions'!K:K,"Pass") | H9: =COUNTIF('File Actions'!K:K,"Fail") | I9: =C9-G9-H9-COUNTIF('File Actions'!K:K,"Blocked")-COUNTIF('File Actions'!K:K,"N/A")
A10: Music | B10: Go to Music | C10: =COUNTA(Music!C:C)-1 | D10: =COUNTIF(Music!J:J,"P0") | E10: =COUNTIF(Music!J:J,"P1") | F10: =COUNTIF(Music!J:J,"P2") | G10: =COUNTIF(Music!K:K,"Pass") | H10: =COUNTIF(Music!K:K,"Fail") | I10: =C10-G10-H10-COUNTIF(Music!K:K,"Blocked")-COUNTIF(Music!K:K,"N/A")
A11: Now Playing | B11: Go to Now Playing | C11: =COUNTA('Now Playing'!C:C)-1 | D11: =COUNTIF('Now Playing'!J:J,"P0") | E11: =COUNTIF('Now Playing'!J:J,"P1") | F11: =COUNTIF('Now Playing'!J:J,"P2") | G11: =COUNTIF('Now Playing'!K:K,"Pass") | H11: =COUNTIF('Now Playing'!K:K,"Fail") | I11: =C11-G11-H11-COUNTIF('Now Playing'!K:K,"Blocked")-COUNTIF('Now Playing'!K:K,"N/A")
A12: Video Player | B12: Go to Video Player | C12: =COUNTA('Video Player'!C:C)-1 | D12: =COUNTIF('Video Player'!J:J,"P0") | E12: =COUNTIF('Video Player'!J:J,"P1") | F12: =COUNTIF('Video Player'!J:J,"P2") | G12: =COUNTIF('Video Player'!K:K,"Pass") | H12: =COUNTIF('Video Player'!K:K,"Fail") | I12: =C12-G12-H12-COUNTIF('Video Player'!K:K,"Blocked")-COUNTIF('Video Player'!K:K,"N/A")
A13: Gestures | B13: Go to Gestures | C13: =COUNTA(Gestures!C:C)-1 | D13: =COUNTIF(Gestures!J:J,"P0") | E13: =COUNTIF(Gestures!J:J,"P1") | F13: =COUNTIF(Gestures!J:J,"P2") | G13: =COUNTIF(Gestures!K:K,"Pass") | H13: =COUNTIF(Gestures!K:K,"Fail") | I13: =C13-G13-H13-COUNTIF(Gestures!K:K,"Blocked")-COUNTIF(Gestures!K:K,"N/A")
A14: Player Panels | B14: Go to Player Panels | C14: =COUNTA('Player Panels'!C:C)-1 | D14: =COUNTIF('Player Panels'!J:J,"P0") | E14: =COUNTIF('Player Panels'!J:J,"P1") | F14: =COUNTIF('Player Panels'!J:J,"P2") | G14: =COUNTIF('Player Panels'!K:K,"Pass") | H14: =COUNTIF('Player Panels'!K:K,"Fail") | I14: =C14-G14-H14-COUNTIF('Player Panels'!K:K,"Blocked")-COUNTIF('Player Panels'!K:K,"N/A")
A15: Settings | B15: Go to Settings | C15: =COUNTA(Settings!C:C)-1 | D15: =COUNTIF(Settings!J:J,"P0") | E15: =COUNTIF(Settings!J:J,"P1") | F15: =COUNTIF(Settings!J:J,"P2") | G15: =COUNTIF(Settings!K:K,"Pass") | H15: =COUNTIF(Settings!K:K,"Fail") | I15: =C15-G15-H15-COUNTIF(Settings!K:K,"Blocked")-COUNTIF(Settings!K:K,"N/A")
A16: Display Tuner | B16: Go to Display Tuner | C16: =COUNTA('Display Tuner'!C:C)-1 | D16: =COUNTIF('Display Tuner'!J:J,"P0") | E16: =COUNTIF('Display Tuner'!J:J,"P1") | F16: =COUNTIF('Display Tuner'!J:J,"P2") | G16: =COUNTIF('Display Tuner'!K:K,"Pass") | H16: =COUNTIF('Display Tuner'!K:K,"Fail") | I16: =C16-G16-H16-COUNTIF('Display Tuner'!K:K,"Blocked")-COUNTIF('Display Tuner'!K:K,"N/A")
A17: Me | B17: Go to Me | C17: =COUNTA(Me!C:C)-1 | D17: =COUNTIF(Me!J:J,"P0") | E17: =COUNTIF(Me!J:J,"P1") | F17: =COUNTIF(Me!J:J,"P2") | G17: =COUNTIF(Me!K:K,"Pass") | H17: =COUNTIF(Me!K:K,"Fail") | I17: =C17-G17-H17-COUNTIF(Me!K:K,"Blocked")-COUNTIF(Me!K:K,"N/A")
A18: Theme | B18: Go to Theme | C18: =COUNTA(Theme!C:C)-1 | D18: =COUNTIF(Theme!J:J,"P0") | E18: =COUNTIF(Theme!J:J,"P1") | F18: =COUNTIF(Theme!J:J,"P2") | G18: =COUNTIF(Theme!K:K,"Pass") | H18: =COUNTIF(Theme!K:K,"Fail") | I18: =C18-G18-H18-COUNTIF(Theme!K:K,"Blocked")-COUNTIF(Theme!K:K,"N/A")
A19: Help | B19: Go to Help | C19: =COUNTA(Help!C:C)-1 | D19: =COUNTIF(Help!J:J,"P0") | E19: =COUNTIF(Help!J:J,"P1") | F19: =COUNTIF(Help!J:J,"P2") | G19: =COUNTIF(Help!K:K,"Pass") | H19: =COUNTIF(Help!K:K,"Fail") | I19: =C19-G19-H19-COUNTIF(Help!K:K,"Blocked")-COUNTIF(Help!K:K,"N/A")
A20: Playlists | B20: Go to Playlists | C20: =COUNTA(Playlists!C:C)-1 | D20: =COUNTIF(Playlists!J:J,"P0") | E20: =COUNTIF(Playlists!J:J,"P1") | F20: =COUNTIF(Playlists!J:J,"P2") | G20: =COUNTIF(Playlists!K:K,"Pass") | H20: =COUNTIF(Playlists!K:K,"Fail") | I20: =C20-G20-H20-COUNTIF(Playlists!K:K,"Blocked")-COUNTIF(Playlists!K:K,"N/A")
A21: Private Folder | B21: Go to Private Folder | C21: =COUNTA('Private Folder'!C:C)-1 | D21: =COUNTIF('Private Folder'!J:J,"P0") | E21: =COUNTIF('Private Folder'!J:J,"P1") | F21: =COUNTIF('Private Folder'!J:J,"P2") | G21: =COUNTIF('Private Folder'!K:K,"Pass") | H21: =COUNTIF('Private Folder'!K:K,"Fail") | I21: =C21-G21-H21-COUNTIF('Private Folder'!K:K,"Blocked")-COUNTIF('Private Folder'!K:K,"N/A")
A22: Media Manager | B22: Go to Media Manager | C22: =COUNTA('Media Manager'!C:C)-1 | D22: =COUNTIF('Media Manager'!J:J,"P0") | E22: =COUNTIF('Media Manager'!J:J,"P1") | F22: =COUNTIF('Media Manager'!J:J,"P2") | G22: =COUNTIF('Media Manager'!K:K,"Pass") | H22: =COUNTIF('Media Manager'!K:K,"Fail") | I22: =C22-G22-H22-COUNTIF('Media Manager'!K:K,"Blocked")-COUNTIF('Media Manager'!K:K,"N/A")
A23: Local Network | B23: Go to Local Network | C23: =COUNTA('Local Network'!C:C)-1 | D23: =COUNTIF('Local Network'!J:J,"P0") | E23: =COUNTIF('Local Network'!J:J,"P1") | F23: =COUNTIF('Local Network'!J:J,"P2") | G23: =COUNTIF('Local Network'!K:K,"Pass") | H23: =COUNTIF('Local Network'!K:K,"Fail") | I23: =C23-G23-H23-COUNTIF('Local Network'!K:K,"Blocked")-COUNTIF('Local Network'!K:K,"N/A")
A24: Not Built | B24: Go to Not Built | C24: =COUNTA('Not Built'!C:C)-1 | D24: =COUNTIF('Not Built'!J:J,"P0") | E24: =COUNTIF('Not Built'!J:J,"P1") | F24: =COUNTIF('Not Built'!J:J,"P2") | G24: =COUNTIF('Not Built'!K:K,"Pass") | H24: =COUNTIF('Not Built'!K:K,"Fail") | I24: =C24-G24-H24-COUNTIF('Not Built'!K:K,"Blocked")-COUNTIF('Not Built'!K:K,"N/A")
A25: TOTAL | C25: =SUM(C5:C24) | D25: =SUM(D5:D24) | E25: =SUM(E5:E24) | F25: =SUM(F5:F24) | G25: =SUM(G5:G24) | H25: =SUM(H5:H24) | I25: =SUM(I5:I24)
A27: How to test: each tab is already sorted P0, then P1, then P2. Finish every P0 before P1. Use the filter arrow on Priority if a sort is cleared.
A28: Write Pass, Fail, Blocked, or N/A in Android Result, Desktop Result, iOS Result, and Web Result. Do not mark Desktop, iOS, or Web playback as Fail only because the engine is not shipped; use N/A and say so in QA Input.
A29: P0 is data loss, playback, permission, PIN, delete, and a control that blocks the main path. P1 is a normal CTA. P2 is cosmetic, rare encoding, or an unwired setting.
A30: Android is the only target with a shipped playback engine. Desktop, iOS, and Web have the UI. Their engines are planned.
A31: There is no bottom tab bar, no login, and no splash. Wide windows use the sidebar. Phones use the Home top bar and chips.
A32: Reference format was QA-UE.xlsx. Columns follow that workbook, with Must Not Happen added because every CTA needs both sides.

Sheet P0 First
A1: # | B1: Screen | C1: Section | D1: Title | E1: Open
A2: 1 | B2: App Shell | C2: Launch | D2: Android permission dialog is the system dialog | E2: Open case
A3: 2 | B3: App Shell | C3: Launch | D3: Cold start opens Home | E3: Open case
A4: 3 | B4: App Shell | C4: Launch | D4: Denial of permission still shows Home | E4: Open case
A5: 4 | B5: App Shell | C5: Launch | D5: No login, OTP, or account gate | E5: Open case
A6: 5 | B6: App Shell | C6: Player host | D6: Android opens playback in its own activity | E6: Open case
A7: 6 | B7: App Shell | C7: Player host | D7: Desktop, iOS, and Web use an embedded overlay | E7: Open case
A8: 7 | B8: App Shell | C8: Player host | D8: Overlay swallows taps while the engine starts | E8: Open case
A9: 8 | B9: App Shell | C9: Sidebar | D9: Sidebar Music opens the right screen | E9: Open case
A10: 9 | B10: App Shell | C10: Sidebar | D10: Sidebar Settings opens the right screen | E10: Open case
A11: 10 | B11: App Shell | C11: Sidebar | D11: Sidebar Videos opens the right screen | E11: Open case
A12: 11 | B12: App Shell | C12: Title bar | D12: Title-bar search opens Search | E12: Open case
A13: 12 | B13: App Shell | C13: Width | D13: Expanded window shows the sidebar | E13: Open case
... A144: 143 | B144: Media Manager | C144: Lists | D144: Recently played is history newest first | E144: Open case

Sheet App Shell
A1: # | B1: Section | C1: Title | D1: Platform | E1: Condition (when it shows) | F1: Flow (Steps) | G1: Expected Result | H1: Must Not Happen | I1: Platform note | J1: Priority | K1: Android Result | L1: Desktop Result | M1: iOS Result | N1: Web Result | O1: QA Input / Clarification
A2: 1 | B2: Launch | C2: Android permission dialog is the system dialog | D2: Android | E2: Screen is reachable | F2: Fresh install on Android. Launch the app. | G2: System permission dialog appears (API 33+: videos, audio, images, notifications; older: storage). App content is set immediately and does not wait for the result. Grant refreshes the library. | H2: Must not show an in-app Grant button or a custom rationale screen. Denial must not crash; Home still opens. | I2: MainActivity requests permissions then still shows App(). | J2: P0
A3: 2 | B3: Launch | C3: Cold start opens Home | D3: Android, Desktop, iOS, Web | E3: Screen is reachable | F3: Install or clear data. Launch Max Player. | G3: Start destination is Home. No splash or onboarding screen. Nav animations are off. | H3: Must not open Me, Settings, or a login screen. Must not wait on a custom permission screen before showing Home. | I3: UI exists on all targets. Playback engine is shipped on Android only. | J3: P0
A4: 3 | B4: Launch | C4: Denial of permission still shows Home | D4: Android | E4: Screen is reachable | F4: Android. Deny every permission. | G4: Home opens. Empty copy asks to grant media access and has no button. | H4: Must not crash or loop the dialog. | I4: UI exists on all targets. Playback engine is shipped on Android only. | J4: P0
A5: 4 | B5: Launch | C5: No login, OTP, or account gate | D5: Android, Desktop, iOS, Web | E5: Screen is reachable | F5: Launch logged-out, airplane mode, and after force-stop. | G5: Library UI is available without an account. | H5: Must not ask for a phone number, OTP, Google account, or MX account. | I5: UI exists on all targets. Playback engine is shipped on Android only. | J5: P0
A6: 5 | B6: Player host | C6: Android opens playback in its own activity | D6: Android | E6: Screen is reachable | F6: Android. Play a video from Home. | G6: Video player activity opens. The library is not covered by an embedded overlay. | H6: Must not draw the desktop 'Initialising player…' overlay on top of Home. | I6: embeddedPlayer is false on Android. | J6: P0
A7: 6 | B7: Player host | C7: Desktop, iOS, and Web use an embedded overlay | D7: Desktop, iOS, Web | E7: Screen is reachable | F7: Desktop, iOS, or Web. Play a video. | G7: A full overlay covers the library while video is requested. If the engine is not ready, a black overlay says Initialising player… / Loading video codecs for the first time and swallows clicks. | H7: Must not let taps reach the library under the overlay. If start fails, the overlay must close rather than stick forever. | I7: Playback engines on these targets are still planned. The overlay must not crash. | J7: P0
A8: 7 | B8: Player host | C8: Overlay swallows taps while the engine starts | D8: Desktop, iOS, Web | E8: Screen is reachable | F8: Desktop, iOS, or Web. Start a video before the engine is ready. | G8: Black overlay, Initialising player…, and Loading video codecs for the first time. Taps do not reach the library. | H8: If start fails, the overlay closes. | I8: UI exists on all targets. Playback engine is shipped on Android only. | J8: P0
A9: 8 | B9: Sidebar | C9: Sidebar Music opens the right screen | D9: Desktop and wide windows | E9: Screen is reachable | F9: Wide window. Tap Music. | G9: Music. Music stays highlighted. Switching sections does not stack history. | H9: Must not push a duplicate of the current screen. Must not open a different section. | I9: Sidebar is hidden below 960 dp. | J9: P0
A10: 9 | B10: Sidebar | C10: Sidebar Settings opens the right screen | D10: Desktop and wide windows | E10: Screen is reachable | F10: Wide window. Tap Settings. | G10: Settings index. Settings, a settings page, and a tuner tab keep it highlighted. Switching sections does not stack history. | H10: Must not push a duplicate of the current screen. Must not open a different section. | I10: Sidebar is hidden below 960 dp. | J10: P0
A11: 10 | B11: Sidebar | C11: Sidebar Videos opens the right screen | D11: Desktop and wide windows | E11: Screen is reachable | F11: Wide window. Tap Videos. | G11: Home. Home, Folder, and Search keep Videos highlighted. Switching sections does not stack history. | H11: Must not push a duplicate of the current screen. Must not open a different section. | I11: Sidebar is hidden below 960 dp. | J11: P0
A12: 11 | B12: Title bar | C12: Title-bar search opens Search | D12: Desktop and wide windows | E12: Screen is reachable | F12: Wide window with a title bar. Type a non-blank query in Search videos. | G12: Search is pushed if not already there. Results filter live. Enter or IME Search saves the query to recent searches. | H12: A blank Enter must not save history. Escape on a non-empty query clears it. Leaving Search clears the title-bar query. | I12: UI exists on all targets. Playback engine is shipped on Android only. | J12: P0
A13: 12 | B13: Width | C13: Expanded window shows the sidebar | D13: Android, Desktop, iOS, Web | E13: Screen is reachable | F13: Use a window at least 960 dp wide (desktop, or a tablet in landscape). | G13: Permanent sidebar: logo, Max Player, PRO chip, LIBRARY, MORE, then Settings and Help. | H13: Must not also show phone shortcut chips or the phone Account icon as a second nav. | I13: UI exists on all targets. Playback engine is shipped on Android only. | J13: P0
... A31: 30 | B31: Unavailable | C31: File Transfer route is not on the home chips | D31: Android, Desktop, iOS, Web | E31: Screen is reachable | F31: Look at Home chips and the sidebar. | G31: There is no File Transfer chip. The unused route exists only if something calls onFileTransfer. | H31: Must not show a File Transfer shortcut on Home. | I31: HomeNavigation.onFileTransfer is unused by ShortcutChips. | J31: P2

Sheet Home
A1: # | B1: Section | C1: Title | D1: Platform | E1: Condition (when it shows) | F1: Flow (Steps) | G1: Expected Result | H1: Must Not Happen | I1: Platform note | J1: Priority | K1: Android Result | L1: Desktop Result | M1: iOS Result | N1: Web Result | O1: QA Input / Clarification
A2: 1 | B2: Chips | C2: Music chip opens Music | D2: Phone and medium windows | E2: Screen is reachable | F2: Phone Home. Tap Music. | G2: Music screen opens. | H2: Must not open the video player. | I2: UI exists on all targets. Playback engine is shipped on Android only. | J2: P0
A3: 2 | B3: Chips | C3: Privacy chip opens Private Folder | D3: Phone and medium windows | E3: Screen is reachable | F3: Phone Home. Tap Privacy. | G3: Private Folder PIN gate opens. | H3: Must not show private files before the PIN. | I3: UI exists on all targets. Playback engine is shipped on Android only. | J3: P0
A4: 3 | B4: Empty | C4: Android empty state has no Grant button | D4: Android | E4: Screen is reachable | F4: Deny media permission. Open Home in folder view with no folders. | G4: Copy is No videos found. Grant media access to scan your device. There is no button. | H4: Must not invent an in-app permission button. Must not loop the system dialog. | I4: UI exists on all targets. Playback engine is shipped on Android only. | J4: P0
A5: 4 | B5: Empty | C5: Web with no folder chosen asks to open a folder | D5: Web | E5: Screen is reachable | F5: Web, no sources. | G5: Choose a folder to add its videos. Every subfolder is included. Button Open folder. | H5: Must not claim the whole device was scanned. | I5: UI exists on all targets. Playback engine is shipped on Android only. | J5: P0
A6: 5 | B6: FAB | C6: Play last is hidden when the setting is off | D6: Android, Desktop, iOS, Web | E6: Screen is reachable | F6: Floating button off. A last-played file exists. | G6: No Play last button and no Continue watching card. | H6: Must not play on launch. | I6: UI exists on all targets. Playback engine is shipped on Android only. | J6: P0
A7: 6 | B7: FAB | C7: Play last plays that file's folder | D7: Phone and medium windows | E7: Screen is reachable | F7: A last-played file still exists and Floating button is on. Phone layout. | G7: FAB Play last plays the last file's folder, sorted with current options, starting at that file (or index 0 if missing). | H7: Must not play the whole library. Must not appear on the wide layout. Must hide if the setting is off or the URI is gone. | I7: UI exists on all targets. Playback engine is shipped on Android only. | J7: P0
A8: 7 | B8: List | C8: Tap a folder opens that folder | D8: Android, Desktop, iOS, Web | E8: Screen is reachable | F8: Folder view with at least one folder. Tap it. | G8: Folder screen opens for that path. | H8: Must not start playback. Must not open a sibling folder. | I8: UI exists on all targets. Playback engine is shipped on Android only. | J8: P0
A9: 8 | B9: Top bar | C9: Account does only its job | D9: Phone and medium windows | E9: Screen is reachable | F9: Phone Home. Tap Account. | G9: Me page opens. | H9: Must not open Settings directly. Must not ask for login. | I9: UI exists on all targets. Playback engine is shipped on Android only. | J9: P0
A10: 9 | B10: Top bar | C10: Files mode title is Videos | D10: Android, Desktop, iOS, Web | E10: Screen is reachable | F10: Open View Menu, choose Files, Done. | G10: Title becomes Videos and the file list is shown. | H10: Must not keep showing folder cards. | I10: UI exists on all targets. Playback engine is shipped on Android only. | J10: P0
A11: 10 | B11: Top bar | C11: Refresh does only its job | D11: Phone and medium windows | E11: Screen is reachable | F11: Phone Home. Tap Refresh. | G11: Library scan starts. A 2 dp progress line shows while loading. | H11: Must not open Search or change the current folder. | I11: UI exists on all targets. Playback engine is shipped on Android only. | J11: P0
A12: 11 | B12: Top bar | C12: Search does only its job | D12: Phone and medium windows | E12: Screen is reachable | F12: Phone Home. Tap Search. | G12: Search screen opens. | H12: Must not start playback. | I12: UI exists on all targets. Playback engine is shipped on Android only. | J12: P0
A13: 12 | B13: Top bar | C13: Title is Folders unless view mode is Files | D13: Phone and medium windows | E13: Screen is reachable | F13: Phone Home. Default view options. | G13: Top bar title is Folders. | H13: Must not say Videos until View Mode is Files. All folders also uses the Folders title. | I13: UI exists on all targets. Playback engine is shipped on Android only. | J13: P0
... A67: 66 | B67: Wide | C67: Wide refresh hides while the title bar has Refresh | D67: Desktop and wide windows | E67: Screen is reachable | F67: Wide Home with a title bar, during a scan. | G67: The title-bar Refresh is the control. The page does not also show a refresh icon. | H67: Must not start two scans from two buttons. | I67: UI exists on all targets. Playback engine is shipped on Android only. | J67: P2

Sheet Folder
A1: # | B1: Section | C1: Title | D1: Platform | E1: Condition (when it shows) | F1: Flow (Steps) | G1: Expected Result | H1: Must Not Happen | I1: Platform note | J1: Priority | K1: Android Result | L1: Desktop Result | M1: iOS Result | N1: Web Result | O1: QA Input / Clarification
A2: 1 | B2: Empty | C2: Empty folder has its own copy | D2: Android, Desktop, iOS, Web | E2: Screen is reachable | F2: Open a folder with no videos. | G2: This folder is empty. | H2: Must not show the Home grant-access copy or Scanning your drives… | I2: UI exists on all targets. Playback engine is shipped on Android only. | J2: P0
A3: 2 | B3: List | C3: Nested videos stay in the child folder | D3: Android, Desktop, iOS, Web | E3: Screen is reachable | F3: Open a parent that contains a subfolder with videos. | G3: Those videos are not in the parent list. Opening the subfolder shows them. | H3: Must not flatten. | I3: UI exists on all targets. Playback engine is shipped on Android only. | J3: P0
A4: 3 | B4: Nav | C4: Back returns to Home | D4: Android, Desktop, iOS, Web | E4: Screen is reachable | F4: Home → folder → back. | G4: Home is shown. Phone back content description is Navigate up. Wide back label is Back. | H4: Must not exit the app. | I4: UI exists on all targets. Playback engine is shipped on Android only. | J4: P0
A5: 4 | B5: Open | C5: Folder title is the last path segment | D5: Android, Desktop, iOS, Web | E5: Screen is reachable | F5: From Home, open a folder named Movies. | G5: Title is Movies, first letter uppercased. Wide subtitle is N videos · size, even if empty. | H5: Must not show the parent path as the title. | I5: UI exists on all targets. Playback engine is shipped on Android only. | J5: P0
A6: 5 | B6: Open | C6: Only direct children are listed | D6: Android, Desktop, iOS, Web | E6: Screen is reachable | F6: Open a folder that has videos and a subfolder with its own videos. | G6: Only files whose folder path equals this folder are listed. | H6: Must not flatten subfolder videos into this list. | I6: UI exists on all targets. Playback engine is shipped on Android only. | J6: P0
A7: 6 | B7: Actions | C7: No folder-level delete or rename | D7: Android, Desktop, iOS, Web | E7: Screen is reachable | F7: Open a folder and inspect the top bar. | G7: Only back, search, and view options. | H7: Must not delete or rename the folder from this screen. | I7: UI exists on all targets. Playback engine is shipped on Android only. | J7: P1
A8: 7 | B8: List | C8: Last played file in this folder is marked | D8: Android, Desktop, iOS, Web | E8: Screen is reachable | F8: Last media in each folder is on. Play a file here, return. | G8: That row title uses the primary colour. Scroll-to-last only runs in list layout when that setting is on and the URI is present. | H8: Grid must not jump via the list scroll state. A file in another folder must not be marked here. | I8: UI exists on all targets. Playback engine is shipped on Android only. | J8: P1
A9: 8 | B9: Nav | C9: Search from a folder searches all videos | D9: Android, Desktop, iOS, Web | E9: Screen is reachable | F9: Inside a folder, tap Search and type a title that exists only in another folder. | G9: That video is found. | H9: Must not limit search to the current folder. | I9: UI exists on all targets. Playback engine is shipped on Android only. | J9: P1
A10: 9 | B10: View | C10: View menu on a folder does not navigate | D10: Android, Desktop, iOS, Web | E10: Screen is reachable | F10: Change layout and tap Done, then Cancel on a second edit. | G10: Done saves and stays on the folder. Cancel discards. | H10: Must not pop to Home. | I10: UI exists on all targets. Playback engine is shipped on Android only. | J10: P1
A11: 10 | B11: View | C11: View options are shared with Home | D11: Android, Desktop, iOS, Web | E11: Screen is reachable | F11: Set Grid on Home. Open a folder. | G11: The folder list uses the same saved options. | H11: Must not keep a separate unsaved layout. | I11: UI exists on all targets. Playback engine is shipped on Android only. | J11: P1
A12: 11 | B12: Wide | C12: Wide subtitle includes a zero count | D12: Desktop and wide windows | E12: Screen is reachable | F12: Open an empty folder on a wide window. | G12: Subtitle is 0 videos · size. Body says This folder is empty. | H12: Must not show the Home empty copy. | I12: UI exists on all targets. Playback engine is shipped on Android only. | J12: P1

Sheet Search
A1: # | B1: Section | C1: Title | D1: Platform | E1: Condition (when it shows) | F1: Flow (Steps) | G1: Expected Result | H1: Must Not Happen | I1: Platform note | J1: Priority | K1: Android Result | L1: Desktop Result | M1: iOS Result | N1: Web Result | O1: QA Input / Clarification
A2: 1 | B2: History | C2: Clear history removes recent searches | D2: Android, Desktop, iOS, Web | E2: Screen is reachable | F2: Settings → General → Clear history → OK. Open Search. | G2: Recent searches is gone. Playback history used for NEW and last-played is also cleared. | H2: Cancel on the confirm dialog must not clear history. Playlists and the private folder must stay. | I2: UI exists on all targets. Playback engine is shipped on Android only. | J2: P0
A3: 2 | B3: Open | C3: Phone search field placeholder | D3: Phone and medium windows | E3: Screen is reachable | F3: Phone. Open Search from Home. | G3: Top bar title Search. Field placeholder Search videos. Back is Navigate up. | H3: Must not show results before a character is typed. | I3: UI exists on all targets. Playback engine is shipped on Android only. | J3: P0
A4: 3 | B4: Play | C4: Playing a result uses the result list as the queue | D4: Android | E4: Screen is reachable | F4: Search returns three files. Play the second. Tap Next. | G4: Next is the third result, not the next file in the folder. | H4: Must not play a hidden non-match. | I4: UI exists on all targets. Playback engine is shipped on Android only. | J4: P0
A5: 4 | B5: Play | C5: Tap a result plays that video | D5: Android | E5: Screen is reachable | F5: Search finds two videos. Tap the second. | G5: Player opens on that file. Queue is the result list. | H5: Must not play the first result. | I5: Other platforms open the embedded player if the engine can start. | J5: P0
A6: 5 | B6: Query | C6: Blank query hides the file list | D6: Android, Desktop, iOS, Web | E6: Screen is reachable | F6: Type a query, then delete it. | G6: Results are cleared. File list is not shown. If history exists, Recent searches is shown. | H6: Must not show every video. Must not show No results for "". | I6: UI exists on all targets. Playback engine is shipped on Android only. | J6: P0
A7: 6 | B7: Query | C7: Live filter matches the file name only | D7: Android, Desktop, iOS, Web | E7: Screen is reachable | F7: Type a partial title that appears in the file name but not as a folder name. | G7: Matching videos appear as you type. Matching is case-insensitive contains on the name. | H7: Must not match path-only text. Must not write recent history on each keystroke. | I7: UI exists on all targets. Playback engine is shipped on Android only. | J7: P0
A8: 7 | B8: History | C8: IME Search saves a recent query | D8: Android, Desktop, iOS, Web | E8: Screen is reachable | F8: Type a query and press the keyboard Search action. | G8: Query is prepended to recent searches, deduped, capped at 20. Blank is ignored. | H8: Must not save on each character. | I8: UI exists on all targets. Playback engine is shipped on Android only. | J8: P1
A9: 8 | B9: History | C9: Tap a recent search fills the query and does not play | D9: Android, Desktop, iOS, Web | E9: Screen is reachable | F9: With history, open Search and tap a past query. | G9: The query is applied and results filter. Nothing plays. | H9: Must not open the player. | I9: UI exists on all targets. Playback engine is shipped on Android only. | J9: P1
A10: 9 | B10: Query | C10: No results copy includes the query | D10: Android, Desktop, iOS, Web | E10: Screen is reachable | F10: Type zzz-no-such-video. | G10: No results for "zzz-no-such-video". | H10: Must not show unrelated files. | I10: UI exists on all targets. Playback engine is shipped on Android only. | J10: P1
A11: 10 | B11: Query | C11: Search is not folder-scoped | D11: Android, Desktop, iOS, Web | E11: Screen is reachable | F11: From a folder, open Search and type a name that exists only elsewhere. | G11: It is found. | H11: Must not show only the current folder. | I11: UI exists on all targets. Playback engine is shipped on Android only. | J11: P1
A12: 11 | B12: Wide | C12: Wide subtitle counts results including zero | D12: Desktop and wide windows | E12: Screen is reachable | F12: Wide Search. Type a query with no matches. | G12: Subtitle is 0 results. Blank query has a null subtitle. | H12: Must not show an in-page search field when the title bar already has one. | I12: UI exists on all targets. Playback engine is shipped on Android only. | J12: P1
A13: 12 | B13: History | C13: History caps at 20 and dedupes | D13: Android, Desktop, iOS, Web | E13: Screen is reachable | F13: Submit 21 different queries, then submit the first one again. | G13: The latest 20 remain, newest first. The repeat moves to the top rather than appearing twice. | H13: Must not grow without a limit. | I13: UI exists on all targets. Playback engine is shipped on Android only. | J13: P2

Sheet File Actions
A1: # | B1: Section | C1: Title | D1: Platform | E1: Condition (when it shows) | F1: Flow (Steps) | G1: Expected Result | H1: Must Not Happen | I1: Platform note | J1: Priority | K1: Android Result | L1: Desktop Result | M1: iOS Result | N1: Web Result | O1: QA Input / Clarification
A2: 1 | B2: Delete | C2: Delete asks, and Cancel keeps the file | D2: Android, Desktop, iOS, Web | E2: Screen is reachable | F2: ⋮ → Delete, or selection Delete. | G2: Dialog title Delete. One file: Delete "name"? Several: Delete N files? Buttons DELETE and CANCEL. | H2: CANCEL must not delete and must not clear selection. DELETE removes the file and, if Delete subtitle files together is on, sibling subtitles. | I2: UI exists on all targets. Playback engine is shipped on Android only. | J2: P0
A3: 2 | B3: Delete | C3: Editing disabled blocks delete and rename | D3: Android, Desktop, iOS, Web | E3: Screen is reachable | F3: Settings → General → Allow editing off. | G3: Sheet Rename and Delete are disabled. Selection-bar Delete toasts Editing is disabled in Settings → General and does not delete. | H3: Must not delete. Must not hide the rows, only disable them. | I3: UI exists on all targets. Playback engine is shipped on Android only. | J3: P0
A4: 3 | B4: Delete | C4: Web and iOS cannot delete files | D4: Web, iOS | E4: Screen is reachable | F4: Web or iOS. Confirm DELETE. | G4: The platform delete returns false. The file remains. Rename toasts Rename failed. | H4: Must not expect the file to disappear. | I4: UI exists on all targets. Playback engine is shipped on Android only. | J4: P0
A5: 4 | B5: Lock | C5: Failed copy does not delete the original | D5: Android, Desktop, iOS, Web | E5: Screen is reachable | F5: iOS, or a full private store. Lock a file. | G5: Toast Could not move file or only the copied count. The original remains if the copy failed. | H5: Must not report N file(s) locked if nothing was copied. | I5: UI exists on all targets. Playback engine is shipped on Android only. | J5: P0
A6: 5 | B6: Lock | C6: No PIN does not move the file | D6: Android, Desktop, iOS, Web | E6: Screen is reachable | F6: Never create a PIN. ⋮ → Lock in Private Folder. | G6: Toast Set up the Private Folder first (Me → Private Folder). The file stays. | H6: Must not delete it. | I6: UI exists on all targets. Playback engine is shipped on Android only. | J6: P0
A7: 6 | B7: Play | C7: Tap a row plays when nothing is selected | D7: Android, Desktop, iOS, Web | E7: Screen is reachable | F7: Files view or a folder with videos. Tap a row. | G7: That file plays. On Android the player activity opens. | H7: Must not enter selection mode. | I7: UI exists on all targets. Playback engine is shipped on Android only. | J7: P0
A8: 7 | B8: Rename | C8: Rename keeps the extension | D8: Android, Desktop, iOS, Web | E8: Screen is reachable | F8: Rename a file video.mkv to Holiday. OK. | G8: Stored name is Holiday.mkv. Toast Renamed on success, Rename failed if the target exists or consent is denied. | H8: CANCEL must keep the old name. A name with no dot must not drop the extension. | I8: UI exists on all targets. Playback engine is shipped on Android only. | J8: P0
A9: 8 | B9: Select | C9: Back clears selection and stays | D9: Android, Desktop, iOS, Web | E9: Screen is reachable | F9: Select two files. Press system back. | G9: Selection clears. The screen stays. | H9: Must not pop Home or Folder. | I9: UI exists on all targets. Playback engine is shipped on Android only. | J9: P0
A10: 9 | B10: Select | C10: Long-press starts selection on phone rows | D10: Phone and medium windows | E10: Screen is reachable | F10: Phone list or phone grid. Long-press a video. | G10: Selection bar appears. Row is selected. System back clears selection and stays on this screen. | H10: Must not pop the screen. Wide grid cards have no long-press, so selection cannot be started that way. | I10: UI exists on all targets. Playback engine is shipped on Android only. | J10: P0
A11: 10 | B11: Select | C11: Selection Play uses only the selected files | D11: Android, Desktop, iOS, Web | E11: Screen is reachable | F11: Select two files that are not the first in the list. Tap Play. | G11: Playback starts at the first selected file, queue is the selection. | H11: Must not play the full folder. | I11: UI exists on all targets. Playback engine is shipped on Android only. | J11: P0
A12: 11 | B12: Sheet | C12: Lock in Private Folder | D12: Android, Desktop, iOS, Web | E12: Screen is reachable | F12: Open the row ⋮ menu and tap Lock in Private Folder. | G12: If no PIN, toast Set up the Private Folder first (Me → Private Folder) and the file stays. After a PIN exists, the file is copied into private storage and the original is deleted only if the copy succeeds. Toast says N file(s) locked in Private Folder. | H12: Must not delete a file that failed to lock. There is no confirm dialog. Selection clears even if lock fails. | I12: UI exists on all targets. Playback engine is shipped on Android only. | J12: P0
A13: 12 | B13: Delete | C13: Android 11+ may show a system consent dialog | D13: Android | E13: Screen is reachable | F13: Android 11 or newer. Confirm DELETE. | G13: The system may ask to allow the delete. Deny: the file remains. The selection may already have been cleared and there is no app toast. | H13: Must not report success if the file is still there. | I13: UI exists on all targets. Playback engine is shipped on Android only. | J13: P1
... A39: 38 | B39: Select | C39: More is hidden while selecting | D39: Android, Desktop, iOS, Web | E39: Screen is reachable | F39: Long-press a row. | G39: The row More icon is hidden. The selection bar is the way out. | H39: Must not open the sheet and the selection bar together from that icon. | I39: UI exists on all targets. Playback engine is shipped on Android only. | J39: P2

Sheet Music
A1: # | B1: Section | C1: Title | D1: Platform | E1: Condition (when it shows) | F1: Flow (Steps) | G1: Expected Result | H1: Must Not Happen | I1: Platform note | J1: Priority | K1: Android Result | L1: Desktop Result | M1: iOS Result | N1: Web Result | O1: QA Input / Clarification
A2: 1 | B2: Mini | C2: Mini player is hidden during video and when idle | D2: Android, Desktop, iOS, Web | E2: Screen is reachable | F2: Stop music. Then play a video. | G2: Mini player hides when the queue is empty and whenever this is not a music session. | H2: Must not cover the video transport. | I2: UI exists on all targets. Playback engine is shipped on Android only. | J2: P0
A3: 2 | B3: Mini | C3: Narrow close stops music | D3: Phone | E3: Screen is reachable | F3: Phone mini player. Tap Close. | G3: Playback stops and the queue clears. The bar hides. | H3: Must not only pause. | I3: UI exists on all targets. Playback engine is shipped on Android only. | J3: P0
A4: 3 | B4: Mini | C4: Narrow mini player controls | D4: Phone | E4: Screen is reachable | F4: Phone, music playing. | G4: Cover, title, artist if known, Play/Pause, Next, Close. Progress is not seekable. Close stops and clears the queue. | H4: Must not show Previous, shuffle, or repeat on the narrow bar. | I4: UI exists on all targets. Playback engine is shipped on Android only. | J4: P0
A5: 4 | B5: Mini | C5: Narrow next does not seek | D5: Phone | E5: Screen is reachable | F5: Phone mini player. Tap Next. | G5: The next song starts at 0. | H5: There is no Previous on the narrow bar. | I5: UI exists on all targets. Playback engine is shipped on Android only. | J5: P0
A6: 5 | B6: Open | C6: Music header and tabs | D6: Android, Desktop, iOS, Web | E6: Screen is reachable | F6: Open Music from the chip or sidebar. | G6: Title Music. Tabs: Tracks, Playlists, Albums, Artists, Folders. Summary counts songs and duration. | H6: Must not list videos. While the first scan runs, a skeleton is shown, not a false empty library. | I6: UI exists on all targets. Playback engine is shipped on Android only. | J6: P0
A7: 6 | B7: Tracks | C7: Play all starts at the first filtered song | D7: Android | E7: Screen is reachable | F7: Tracks tab, search empty. Tap Play all. | G7: Music session starts at index 0 of the filtered list. Mini player appears. | H7: Must not shuffle unless Shuffle was used. | I7: Other platforms depend on the unshipped engine. | J7: P0
A8: 7 | B8: Empty | C8: No music found after scan | D8: Android, Desktop, iOS, Web | E8: Screen is reachable | F8: Device with no audio, scan finished. | G8: No music found. | H8: Must not show video files as songs. | I8: UI exists on all targets. Playback engine is shipped on Android only. | J8: P1
A9: 8 | B9: Groups | C9: Album, artist, and folder drill-in | D9: Android, Desktop, iOS, Web | E9: Screen is reachable | F9: Open an album, then Play and Shuffle in the header. Back. | G9: Only that group's songs play. Back returns to the tab. | H9: Unknown artist, Unknown album, and Unknown folder are the empty labels. | I9: UI exists on all targets. Playback engine is shipped on Android only. | J9: P1
A10: 9 | B10: Mini | C10: Wide mini player seek, volume, and repeat | D10: Desktop and wide windows | E10: Screen is reachable | F10: Wide window, music playing. | G10: Favourite, Shuffle, Previous, Play/Pause, Next, Repeat. Seek commits on release. Volume toggles mute and the slider sets player volume 0 to 1. | H10: Previous is the engine previous, not the video Smart Previous. Close clears the queue. | I10: UI exists on all targets. Playback engine is shipped on Android only. | J10: P1
A11: 10 | B11: Mini | C11: Wide previous is not smart previous | D11: Desktop and wide windows | E11: Screen is reachable | F11: Wide mini player. Seek past 10 seconds. Tap Previous. | G11: The engine previous runs. It does not use the video 3-second rule. | H11: Must not rewind 10 seconds unless the engine previous does that. | I11: UI exists on all targets. Playback engine is shipped on Android only. | J11: P1
A12: 11 | B12: Mini | C12: Wide repeat cycles Off, All, One | D12: Desktop and wide windows | E12: Screen is reachable | F12: Tap Repeat three times. | G12: Off, then All, then One, then Off. Accent when not Off. | H12: Must not open the video loop toasts. | I12: UI exists on all targets. Playback engine is shipped on Android only. | J12: P1
A13: 12 | B13: Playlists | C13: Create, Favourites, and Recently Played cards | D13: Android, Desktop, iOS, Web | E13: Screen is reachable | F13: Playlists tab. | G13: Cards: New playlist / Create, Favourites, Recently Played, then user playlists. | H13: A blank playlist name must not create a playlist. Favourites lists only hearted URIs. | I13: UI exists on all targets. Playback engine is shipped on Android only. | J13: P1
... A30: 29 | B30: Sort | C30: Sort by Title | D30: Android, Desktop, iOS, Web | E30: Screen is reachable | F30: Open Sort and choose Title. | G30: Label becomes Sort: Title. Rows reorder. | H30: Must not offer the video-only sort keys (Resolution, Frame rate, Status). | I30: UI exists on all targets. Playback engine is shipped on Android only. | J30: P2

Sheet Now Playing
A1: # | B1: Section | C1: Title | D1: Platform | E1: Condition (when it shows) | F1: Flow (Steps) | G1: Expected Result | H1: Must Not Happen | I1: Platform note | J1: Priority | K1: Android Result | L1: Desktop Result | M1: iOS Result | N1: Web Result | O1: QA Input / Clarification
A2: 1 | B2: Back | C2: Back does not stop playback | D2: Android, Desktop, iOS, Web | E2: Screen is reachable | F2: Tap Back. | G2: Now Playing closes. The mini player still shows and audio continues. | H2: Must not clear the queue. | I2: UI exists on all targets. Playback engine is shipped on Android only. | J2: P0
A3: 2 | B3: Open | C3: Tap the mini player opens Now Playing | D3: Android, Desktop, iOS, Web | E3: Screen is reachable | F3: Music is playing. Tap the mini player bar (not a button). | G3: Now Playing opens. Compact header says NOW PLAYING. Back pill says Back. | H3: Must not stop playback. | I3: UI exists on all targets. Playback engine is shipped on Android only. | J3: P0
A4: 3 | B4: Transport | C4: Next and previous | D4: Android | E4: Screen is reachable | F4: Queue of three songs. Tap Next, then Previous. | G4: Next advances. Previous uses the engine previous, not the video 3-second smart rule. | H4: Must not apply Next/Prev → FF/Rew from video settings. | I4: UI exists on all targets. Playback engine is shipped on Android only. | J4: P0
A5: 4 | B5: Transport | C5: Play and pause | D5: Android | E5: Screen is reachable | F5: Tap Pause, then Play. | G5: Audio pauses and resumes. The icon swaps. | H5: Must not skip to the next track. | I5: UI exists on all targets. Playback engine is shipped on Android only. | J5: P0
A6: 5 | B6: A-B | C6: Second tap sets B at least 500 ms after A | D6: Android, Desktop, iOS, Web | E6: Screen is reachable | F6: Tap A-B at a position, then again 100 ms later. | G6: B is at least 500 ms after A. Third tap clears it. | H6: Must not toast B must be after A; that toast is the video panel. | I6: UI exists on all targets. Playback engine is shipped on Android only. | J6: P1
A7: 6 | B7: A-B | C7: Three taps set, enable, and clear A-B | D7: Android | E7: Screen is reachable | F7: Tap A-B three times. | G7: First toast A point set. Second toast A-B repeat on, B at least 500 ms after A. Third toast A-B repeat off. | H7: Must not use the video A-B panel state. | I7: UI exists on all targets. Playback engine is shipped on Android only. | J7: P1
A8: 7 | B8: Equalizer | C8: Button is visible even when the effect engine is missing | D8: Android, Desktop, iOS, Web | E8: Screen is reachable | F8: iOS or Web. Tap Equalizer. | G8: The panel opens and says Equalizer is not available for this audio output. | H8: Must not show live bands that do nothing. Android and desktop VLC show On/Off, presets, reverb, and bass boost. | I8: UI exists on all targets. Playback engine is shipped on Android only. | J8: P1
A9: 8 | B9: Lyrics | C9: Lyrics always says none | D9: Android, Desktop, iOS, Web | E9: Screen is reachable | F9: Tap Lyrics on a song that has embedded lyrics and on one that does not. | G9: Toast No lyrics found either way. | H9: Must not open a lyrics panel. | I9: UI exists on all targets. Playback engine is shipped on Android only. | J9: P1
A10: 9 | B10: More | C10: Share and add to playlist | D10: Android, Desktop, iOS, Web | E10: Screen is reachable | F10: Tap More, then Share, and Add to playlist. | G10: Share uses the platform share. Add to playlist is present because Music passes the slot. | H10: Lyrics always toasts No lyrics found and must not open a lyrics view. | I10: UI exists on all targets. Playback engine is shipped on Android only. | J10: P1
A11: 10 | B11: Queue | C11: Up next search and jump | D11: Android, Desktop, iOS, Web | E11: Screen is reachable | F11: Open the queue. Search for a title. Tap it. Search for nonsense. | G11: Wide shows Up next and N tracks. Placeholder Search in queue. No match says No matching tracks. Tap seeks to that index at 0 and plays. | H11: Must not delete the track. | I11: UI exists on all targets. Playback engine is shipped on Android only. | J11: P1
A12: 11 | B12: Seek | C12: Drag previews and commits on release | D12: Android | E12: Screen is reachable | F12: Drag the seek bar, then release. | G12: Time preview follows the finger. Position changes on release. Right side shows remaining time or --:--. | H12: Must not seek on every pixel if the finger is still down, beyond the preview. | I12: UI exists on all targets. Playback engine is shipped on Android only. | J12: P1
A13: 12 | B13: Speed | C13: Chip 0.5x | D13: Android, Desktop, iOS, Web | E13: Screen is reachable | F13: Tap Speed and choose 0.5x. | G13: Engine speed changes and the sheet closes. The button shows the speed when it is not 1x. | H13: Must not show 0.25x, 3x, or 4x on this sheet. | I13: UI exists on all targets. Playback engine is shipped on Android only. | J13: P1
... A22: 21 | B22: Share | C22: Share uses the current song | D22: Android, Desktop, iOS, Web | E22: Screen is reachable | F22: Tap Share. | G22: The platform share runs for this file. | H22: Must not share the previous song. | I22: UI exists on all targets. Playback engine is shipped on Android only. | J22: P2

Sheet Video Player
A1: # | B1: Section | C1: Title | D1: Platform | E1: Condition (when it shows) | F1: Flow (Steps) | G1: Expected Result | H1: Must Not Happen | I1: Platform note | J1: Priority | K1: Android Result | L1: Desktop Result | M1: iOS Result | N1: Web Result | O1: QA Input / Clarification
A2: 1 | B2: Background | C2: Leaving the app follows Background/PiP mode | D2: Android | E2: Screen is reachable | F2: Set the mode to Stop, then Background play, then Picture-in-Picture. Play a video and switch apps. | G2: Stop pauses. Background play continues audio with the notification. PiP enters PiP when the device supports it. Audio-only can continue when Background play (audio) is on. Background play also posts the Android playback notification and lock-screen controls through PlaybackService. Tapping the notification returns to the player. Removing the app from recents stops the service if playback has ended or is not playing. | H2: Headset disconnect pauses when Pause on headset disconnected is on. Play alone should duck or stop other players. | I2: UI exists on all targets. Playback engine is shipped on Android only. | J2: P0
A3: 2 | B3: Chrome | C3: Navigate up closes the player | D3: Android, Desktop, iOS, Web | E3: Screen is reachable | F3: Tap Navigate up. | G3: Android finishes the activity and stops the engine. Desktop/Web clears the overlay. | H3: Must not delete the file. Must not return to a random screen. | I3: UI exists on all targets. Playback engine is shipped on Android only. | J3: P0
A4: 3 | B4: Chrome | C4: Next, previous, and last item | D4: Android | E4: Screen is reachable | F4: Queue of two videos. Tap Next until the end. Tap Previous after 4 seconds, and again in the first 3 seconds. | G4: Next on the last item toasts Last item. Smart Previous (default on) seeks to 0 if position is over 3 seconds; otherwise it opens the previous file. | H4: If Next/Prev → FF/Rew is on, these buttons seek by the move interval and must not change files. | I4: UI exists on all targets. Playback engine is shipped on Android only. | J4: P0
A5: 4 | B5: Chrome | C5: Play and pause | D5: Android | E5: Screen is reachable | F5: Show controls. Tap Play/Pause. Also try when the file has ended. | G5: Toggles playback. If ended, seeks to 0 then plays. | H5: Must not skip. | I5: UI exists on all targets. Playback engine is shipped on Android only. | J5: P0
A6: 5 | B6: Chrome | C6: Single back asks twice when the setting is on | D6: Android | E6: Screen is reachable | F6: Settings → Player → Double-tap the back button on. Press system back once, wait, press again within 2 seconds, then again after 2 seconds. | G6: First press toasts Press back again to exit and stays. A second press within 2 seconds closes. After 2 seconds the warning repeats. | H6: If a panel is open, the first back closes the panel and must not exit. If locked, back only shows the lock icon and must not unlock or exit. | I6: UI exists on all targets. Playback engine is shipped on Android only. | J6: P0
A7: 6 | B7: Error | C7: All-files access dialog | D7: Android | E7: Screen is reachable | F7: Android 11+ file that needs all-files access. | G7: Dialog explains All files access. ALLOW opens settings. CANCEL closes the player. If the platform cannot request access, ALLOW closes. | H7: Must not keep a black player open after CANCEL. | I7: UI exists on all targets. Playback engine is shipped on Android only. | J7: P0
A8: 7 | B8: Error | C8: Unplayable file offers OK and sometimes SW | D8: Android | E8: Screen is reachable | F8: Open a corrupt file, then a file that fails for a non-IO reason while on HW. | G8: Can't play this media. and the code name. OK goes to the next item or closes. TRY SW DECODER appears only when the error is not IO and the decoder is not already SW. | H8: Suppress error message skips to the next video with no dialog, but the dialog still shows if there is no next item. | I8: UI exists on all targets. Playback engine is shipped on Android only. | J8: P0
A9: 8 | B9: Lock | C9: Lock blocks every gesture | D9: Android, Desktop, iOS, Web | E9: Screen is reachable | F9: Tap Lock. Try seek, volume, brightness, double-tap, and long-press. | G9: Transport hides. Only the small lock icon can return, for 2.5 seconds after a touch. | H9: Must not seek or change volume. Normal lock: tap the icon unlocks. Kids lock: tap toasts Long press to unlock and stays locked. | I9: UI exists on all targets. Playback engine is shipped on Android only. | J9: P0
A10: 9 | B10: Open | C10: Video opens and plays | D10: Android | E10: Screen is reachable | F10: Android. Tap a video. | G10: Player activity opens, surface shows the frame, playback starts unless a resume dialog is waiting. | H10: Must not stay on a black screen with audio from a different file. Title is the file title. | I10: UI exists on all targets. Playback engine is shipped on Android only. | J10: P0
A11: 10 | B11: PiP | C11: Popup enters picture-in-picture on Android | D11: Android | E11: Screen is reachable | F11: Android 8+ with PiP. Tap Popup. Then try on a device without PiP. | G11: Activity enters PiP. Controls, panels, and dialogs hide. Failure toasts Picture-in-picture not supported. | H11: Button must not appear on iOS or desktop. Web shows it only if the browser exposes picture-in-picture. | I11: UI exists on all targets. Playback engine is shipped on Android only. | J11: P0
A12: 11 | B12: Playback | C12: Decoder change keeps the position | D12: Android | E12: Screen is reachable | F12: Note the time. Switch HW to SW. | G12: Playback restarts at the same item and position. Toast names the decoder. | H12: Must not restart at 0 unless the engine cannot seek. | I12: UI exists on all targets. Playback engine is shipped on Android only. | J12: P0
A13: 12 | B13: Playback | C13: Double-tap back is a single press when off | D13: Android | E13: Screen is reachable | F13: Double-tap the back button off. Press system back once. | G13: The player closes immediately, unless a panel is open or the player is locked. | H13: Must not toast Press back again to exit. | I13: UI exists on all targets. Playback engine is shipped on Android only. | J13: P0
... A77: 76 | B77: Shortcuts | C77: Shortcuts switch hides the row | D77: Android, Desktop, iOS, Web | E77: Screen is reachable | F77: More → Shortcuts off. | G77: The shortcut row disappears. Playback continues. | H77: Must not hide the seek bar. | I77: UI exists on all targets. Playback engine is shipped on Android only. | J77: P2

Sheet Gestures
A1: # | B1: Section | C1: Title | D1: Platform | E1: Condition (when it shows) | F1: Flow (Steps) | G1: Expected Result | H1: Must Not Happen | I1: Platform note | J1: Priority | K1: Android Result | L1: Desktop Result | M1: iOS Result | N1: Web Result | O1: QA Input / Clarification
A2: 1 | B2: Brightness | C2: Left-half vertical swipe changes brightness | D2: Android | E2: Screen is reachable | F2: Brightness gesture on. Swipe up and down on the left half. | G2: Left pill shows a brightness icon and a value 0 to 30. Release saves Brightness level. Android also sets window brightness. | H2: Must not change volume. Must not run on the right half. iOS does not change system brightness. | I2: UI exists on all targets. Playback engine is shipped on Android only. | J2: P0
A3: 2 | B3: Double tap | C3: Sides seek by the move interval | D3: Android | E3: Screen is reachable | F3: FF/RW (Double tap) on. Move interval 10. Double-tap the right third twice, then the left third. | G3: Right seeks forward and shows an accumulating seconds badge. Left rewinds. Same direction accumulates. | H3: Must not play/pause on the sides while FF/RW is enabled. Center double-tap pauses and shows Playing or Paused. | I3: UI exists on all targets. Playback engine is shipped on Android only. | J3: P0
A4: 3 | B4: Keyboard | C4: Left and Right | D4: Desktop, Web | E4: Screen is reachable | F4: Desktop or Web player, unlocked. Press Left and Right. | G4: Seek by the move interval. Shift seeks 1 minute. Ctrl or Cmd with arrows changes items. | H4: Must not run on Android or iOS. Must not run while locked. | I4: UI exists on all targets. Playback engine is shipped on Android only. | J4: P0
A5: 4 | B5: Keyboard | C5: Space or K | D5: Desktop, Web | E5: Screen is reachable | F5: Desktop or Web player, unlocked. Press Space or K. | G5: Play and pause. No center pill. | H5: Must not run on Android or iOS. Must not run while locked. | I5: UI exists on all targets. Playback engine is shipped on Android only. | J5: P0
A6: 5 | B6: Keyboard | C6: Up and Down | D6: Desktop, Web | E6: Screen is reachable | F6: Desktop or Web player, unlocked. Press Up and Down. | G6: Volume up and down by one system step. | H6: Must not run on Android or iOS. Must not run while locked. | I6: UI exists on all targets. Playback engine is shipped on Android only. | J6: P0
A7: 6 | B7: Long press | C7: Long-press fast-forwards only while held and playing | D7: Android | E7: Screen is reachable | F7: Speed FF (Long press) on. While playing, long-press without dragging. Release. Repeat while paused. | G7: Top pill says N.NX Speed Playing at the Speed FF value (default 2.0). Release restores the old speed. Paused long-press does nothing. | H7: Must not seek. Must not stick at 2x after release. Locked screen must ignore it. | I7: UI exists on all targets. Playback engine is shipped on Android only. | J7: P0
A8: 7 | B8: Seek | C8: Horizontal swipe seeks | D8: Android | E8: Screen is reachable | F8: Seek position on. Swipe right, then left. | G8: OSD shows the target time and a + or − offset. Position commits on finger up. Seek speed default is 10 sec/cm. | H8: With the flag off, a horizontal swipe must not seek. With Display the current position off, the thumb must not move live. | I8: UI exists on all targets. Playback engine is shipped on Android only. | J8: P0
A9: 8 | B9: Tap | C9: Default tap shows and hides controls | D9: Android | E9: Screen is reachable | F9: Touch action is Show/hide interface. Tap the video, wait, tap again. | G9: Controls toggle. If a panel is open, the tap closes the panel instead. | H9: Must not pause. Must not fire while locked or during a drag. | I9: UI exists on all targets. Playback engine is shipped on Android only. | J9: P0
A10: 9 | B10: Volume | C10: Right-half vertical swipe changes volume | D10: Android | E10: Screen is reachable | F10: Volume gesture on. Volume boost on. Swipe up on the right half past the system max. | G10: Right pill shows volume. Above the system max the bar can enter the boost range, up to 200%, and turns orange. | H10: Must not change brightness. With Volume boost off, it must not exceed 100%. Increasing while muted unmutes. | I10: UI exists on all targets. Playback engine is shipped on Android only. | J10: P0
A11: 10 | B11: Double tap | C11: Center zoom only when that flag is on | D11: Android, Desktop, iOS, Web | E11: Screen is reachable | F11: Turn on Video zoom (Double tap). Double-tap the center. | G11: Zoom cycles and a toast shows the zoom name. | H11: With the flag off, center double-tap must pause, not zoom. | I11: UI exists on all targets. Playback engine is shipped on Android only. | J11: P1
A12: 11 | B12: Gesture | C12: Brightness does not run on the right half | D12: Android | E12: Screen is reachable | F12: Swipe vertically on the right half. | G12: Volume changes. Brightness does not. | H12: Must not move both. | I12: UI exists on all targets. Playback engine is shipped on Android only. | J12: P1
A13: 12 | B13: Gesture | C13: Brightness flag off ignores a left swipe | D13: Android | E13: Screen is reachable | F13: Brightness gesture off. Swipe the left half. | G13: Brightness stays. The Screen brightness checkbox is a different setting. | H13: Must not dim the video. | I13: UI exists on all targets. Playback engine is shipped on Android only. | J13: P1
... A53: 52 | B53: Unwired | C53: Playback Speed gesture flag does nothing | D53: Android, Desktop, iOS, Web | E53: Screen is reachable | F53: Controls → Gestures → Playback Speed on. Try every swipe. | G53: No swipe changes playback speed. Speed still changes from the Speed panel. | H53: Must not treat this checkbox as a working gesture. | I53: UI exists on all targets. Playback engine is shipped on Android only. | J53: P2

Sheet Player Panels
A1: # | B1: Section | C1: Title | D1: Platform | E1: Condition (when it shows) | F1: Flow (Steps) | G1: Expected Result | H1: Must Not Happen | I1: Platform note | J1: Priority | K1: Android Result | L1: Desktop Result | M1: iOS Result | N1: Web Result | O1: QA Input / Clarification
A2: 1 | B2: Audio | C2: Audio track list and disable | D2: Android | E2: Screen is reachable | F2: Open Audio Track on a file with two tracks, and on a file with none. | G2: Radios use the engine labels. Empty says No audio tracks found. Disable clears the selection where the browser can switch. | H2: Web without native tracks opens Switch audio in {browser} instead of switching. Use SW audio decoder appears only where decoder choice exists. | I2: UI exists on all targets. Playback engine is shipped on Android only. | J2: P0
A3: 2 | B3: Decoder | C3: HW, HW+, and SW | D3: Android | E3: Screen is reachable | F3: Android. Tap the HW/HW+/SW chip. Pick each row. | G3: Dialog title Select decoder. Choosing one restarts playback at the same position and toasts the label. HW+ behaves like HW. | H3: The chip must not appear on iOS or Web. Desktop shows it only when VLC is available. | I3: UI exists on all targets. Playback engine is shipped on Android only. | J3: P0
